Workbook

Sheet 市场
A1: 目录：
A2: 1、女装类目&价位段分布
A3: 2、高端的市场份额、价格趋势
A4: 3、高端的主要卖家&爆款
A5: 4、高端的产品分析
A6: 5、总结
A7: 数据源： similarweb
A9: 1、女装类目&价位段分布
A10: *各类目TOP1000
A11: 类目 | B11: 销售件数 | C11: 销售件数 YOY | D11: GMV $ | E11: GMV YOY | F11: 均价 | G11: 价格分布 | H11: 低价位 $ | I11: 中低价位 $ | J11: 中价位（主流） $ | K11: 中高价位 $ | L11: 高价位 $ | M11: 列1
A12: Lingerie, Sleep & Lounge | B12: 172600000 | C12: 0.341 | D12: 3600000000 | E12: 0.29 | F12: =D12/B12 -> 20.857474
A13: Dresses | B13: 92700000 | C13: 0.519 | D13: 3400000000 | E13: 0.461 | F13: =D13/B13 -> 36.677454 | G13: =_xlfn.DISPIMG("ID_4EE87D3B08A444348ADAB1F47B9C62AA",1) -> =DISPIMG("ID_4EE87D3B08A444348ADAB1F47B9C62AA",1) | H13: 11.19~20.53 $ | I13: 20.53~35.31 $ | J13: 35.31~49.5 $ | K13: 49.5~59.42 $ | L13: 59.42~698.0 $ | M13: *哪些
A14: Tops, Tees & Blouses | B14: 204800000 | C14: 0.912 | D14: 3200000000 | E14: 0.542 | F14: =D14/B14 -> 15.625 | G14: =_xlfn.DISPIMG("ID_5B9773B6EE9D49198E4666AA34E55215",1) -> =DISPIMG("ID_5B9773B6EE9D49198E4666AA34E55215",1) | H14: 0~15.0 $ | I14: 15.0~20.0 $ | J14: 20.0~25.0 $ | K14: 25.0~30.0 $ | L14: 30.0~157.98 $
A15: Active | B15: 105900000 | C15: 0.426 | D15: 2300000000 | E15: 0.366 | F15: =D15/B15 -> 21.718602 | G15: =_xlfn.DISPIMG("ID_2639E6F6495A430E9D56A9FE207D720B",1) -> =DISPIMG("ID_2639E6F6495A430E9D56A9FE207D720B",1) | H15: 6.71~9.47 $ | I15: 9.47~17.63 $ | J15: 17.63~30.54 $ | K15: 30.54~44.3 $ | L15: 44.3~368.1 $
A16: Sweaters | B16: 39200000 | C16: 0.658 | D16: 1000000000 | E16: 0.435 | F16: =D16/B16 -> 25.510204 | G16: =_xlfn.DISPIMG("ID_AFE94619D875444080B1250CC088CD9E",1) -> =DISPIMG("ID_AFE94619D875444080B1250CC088CD9E",1) | H16: 9.17~14.97 $ | I16: 14.97~23.08 $ | J16: 23.08~35.43 $ | K16: 35.43~43.41 $ | L16: 43.41~52.48 $
A17: Jeans | B17: 26900000 | C17: 0.638 | D17: 934800000 | E17: 0.632 | F17: =D17/B17 -> 34.750929 | G17: =_xlfn.DISPIMG("ID_F664C8527D2A461D90603A89B2552515",1) -> =DISPIMG("ID_F664C8527D2A461D90603A89B2552515",1) | H17: 14.41~18.88 $ | I17: 18.88~31.55 $ | J17: 31.55~42.53 $ | K17: 42.53~58.8 $ | L17: 58.8~278.0 $
A18: Coats, Jackets & Vests | B18: 19400000 | C18: 0.332 | D18: 848500000 | E18: 0.309 | F18: =D18/B18 -> 43.737113 | G18: =_xlfn.DISPIMG("ID_30DB389ABF264B92B3A156DA7EA225E0",1) -> =DISPIMG("ID_30DB389ABF264B92B3A156DA7EA225E0",1) | H18: 0~40.0 $ | I18: 40.0~65.0 $ | J18: 65.0~90.0 $ | K18: 90.0~115.0 $ | L18: 115.0~350.0 $
A19: Pants | B19: 21900000 | C19: 0.852 | D19: 600300000 | E19: 0.724 | F19: =D19/B19 -> 27.410959 | G19: =_xlfn.DISPIMG("ID_F10402315EA74203B0321F0B5439D55C",1) -> =DISPIMG("ID_F10402315EA74203B0321F0B5439D55C",1) | H19: 11.26~17.91 $ | I19: 17.91~25.88 $ | J19: 25.88~33.5 $ | K19: 33.5~39.79 $ | L19: 39.79~51.38 $
A20: Socks & Hosiery | B20: 40100000 | C20: 0.343 | D20: 504400000 | E20: 0.268 | F20: =D20/B20 -> 12.578554
A21: Jumpsuits, Rompers & Overalls | B21: 15800000 | C21: 0.124 | D21: 489200000 | E21: 0.125 | F21: =D21/B21 -> 30.962025 | G21: =_xlfn.DISPIMG("ID_F24D2431C5614774842DCAE816F3723E",1) -> =DISPIMG("ID_F24D2431C5614774842DCAE816F3723E",1) | H21: 13.69~19.44 $ | I21: 19.44~28.94 $ | J21: 28.94~39.65 $ | K21: 39.65~58.32 $ | L21: 58.32~147.66 $
A22: Fashion Hoodies & Sweatshirts | B22: 18700000 | C22: 0.301 | D22: 451400000 | E22: 0.166 | F22: =D22/B22 -> 24.139037 | G22: =_xlfn.DISPIMG("ID_4BF610D01CBA42F1B5CE1D69812C283D",1) -> =DISPIMG("ID_4BF610D01CBA42F1B5CE1D69812C283D",1) | H22: 7.08~14.3 $ | I22: 14.3~23.47 $ | J22: 23.47~31.74 $ | K22: 31.74~48.92 $ | L22: 48.92~124.88 $
A23: Shorts | B23: 10700000 | C23: 0.61 | D23: 283300000 | E23: 0.624 | F23: =D23/B23 -> 26.476636 | G23: =_xlfn.DISPIMG("ID_23419B262AF0443E979DBA2B6EEF3842",1) -> =DISPIMG("ID_23419B262AF0443E979DBA2B6EEF3842",1) | H23: 11.24~17.22 $ | I23: 17.22~25.18 $ | J23: 25.18~32.02 $ | K23: 32.02~37.34 $ | L23: 37.34~365.0 $
A24: Clothing Sets | B24: 6700000 | C24: 1.132 | D24: 214600000 | E24: 0.989 | F24: =D24/B24 -> 32.029851 | G24: =_xlfn.DISPIMG("ID_5FE54769FE28412D815304E552E77B9D",1) -> =DISPIMG("ID_5FE54769FE28412D815304E552E77B9D",1) | H24: 14.99~21.39 $ | I24: 21.39~30.27 $ | J24: 30.27~38.7 $ | K24: 38.7~46.28 $ | L24: 46.28~57.63 $
A25: Suiting & Blazers | B25: 4600000 | C25: 0.555 | D25: 207700000 | E25: 0.574 | F25: =D25/B25 -> 45.152174 | G25: =_xlfn.DISPIMG("ID_27788D9E5D964FC2AFC98ABAC078889E",1) -> =DISPIMG("ID_27788D9E5D964FC2AFC98ABAC078889E",1) | H25: 10.64~15.65 $ | I25: 15.65~21.99 $ | J25: 21.99~32.65 $ | K25: 32.65~40.14 $ | L25: 40.14~142.06 $
A26: Skirts | B26: 5600000 | C26: 0.417 | D26: 145700000 | E26: 0.386 | F26: =D26/B26 -> 26.017857 | G26: =_xlfn.DISPIMG("ID_06CDA42564C043EA9AC97DE507611236",1) -> =DISPIMG("ID_06CDA42564C043EA9AC97DE507611236",1) | H26: 10.64~15.65 $ | I26: 15.65~21.99 $ | J26: 21.99~32.65 $ | K26: 32.65~40.14 $ | L26: 40.14~142.06 $
A27: Leggings | B27: 6900000 | C27: 0.335 | D27: 129100000 | E27: 0.245 | F27: =D27/B27 -> 18.710145 | G27: =_xlfn.DISPIMG("ID_ECB4593ED076403CB332DE222A6B3509",1) -> =DISPIMG("ID_ECB4593ED076403CB332DE222A6B3509",1) | H27: 0~15.0 $ | I27: 15.0~25.0 $ | J27: 25.0~35.0 $ | K27: 35.0~45.0 $ | L27: 45.0~105.34 $
A28: Bodysuits | B28: =4.5*1000000 -> 4500000 | C28: 0.042 | D28: 96900000 | E28: 0.115 | F28: =D28/B28 -> 21.533333 | G28: =_xlfn.DISPIMG("ID_1B6FBA744EF341D1AF64C4C02217884D",1) -> =DISPIMG("ID_1B6FBA744EF341D1AF64C4C02217884D",1) | H28: 7.8~14.22 $ | I28: 14.22~19.73 $ | J28: 19.73~28.19 $ | K28: 28.19~35.99 $ | L28: 35.99~44.9 $
A31: 2、高端的市场份额、价格趋势
A32: 2.1 Dress
A33: 中价位(35-49元)占46%主导，高端仅3.5%但价格上涨趋势强
A35: 价位段 | B35: 价格区间标注$ | C35: ASIN数量 | D35: 总GMV | E35: GMV占比(%)
A36: 低价位 | B36: 11.19~20.53元 | C36: 78 | D36: 18772093 | E36: 6.56
A37: 中低价位 | B37: 20.53~35.31元 | C37: 194 | D37: 58650701 | E37: 20.48
A38: 中价位 | B38: 35.31~49.5元 | C38: 470 | D38: 132374038 | E38: 46.23
A39: 中高价位 | B39: 49.5~59.42元 | C39: 225 | D39: 66570286 | E39: 23.25
A40: 高价位 | B40: 59.42~698.0元 | C40: 33 | D40: 9952905 | E40: 3.48
A44: 📊 2024→2025 各价位段价格变化分析
A46: 价位段 | B46: 价格区间 | C46: 上涨 | D46: 下跌 | E46: 不变 | F46: 合计 | G46: 上涨占比(%) | H46: 下跌占比(%) | I46: 不变占比(%)
A47: 低价位 | B47: 11.19~20.53元 | C47: 0 | D47: 4 | E47: 0 | F47: 4 | G47: 0 | H47: 100 | I47: 0
A48: 中低价位 | B48: 20.53~35.31元 | C48: 28 | D48: 67 | E48: 2 | F48: 97 | G48: 28.9 | H48: 69.1 | I48: 2.1
...

Sheet Sheet1
A1: Tops, Tees & Blouses（上衣） | B1: 0.114
A2: Coats, Jackets & Vests | B2: 0.177
A3: Dresses | B3: 0.267
A4: Active | B4: 0.25
A5: Jeans | B5: 0.271
A6: Sweaters | B6: 0.253
A7: Jumpsuits, Rompers & Overalls（Jumpsuit） | B7: 0.27
A8: Fashion Hoodies & Sweatshirts | B8: 0.287
A9: Pants | B9: 0.222
A10: Shorts | B10: 0.295
A11: Leggings | B11: 0.231
A12: Suiting & Blazers | B12: 0.228
... A14: Bodysuits | B14: 0.301
A20: 品类 | B20: 中高价位区间 | C20: 价格上涨占比（%）
A21: Tops, Tees & Blouses | B21: 25.0~30.0 元 | C21: 26.1
A22: Coats, Jackets & Vests | B22: 90.0~115.0 元 | C22: 38.1
A23: Dresses | B23: 49.5~59.42 元 | C23: 78.8
A24: Active | B24: 30.54~44.3 元 | C24: 35.5
A25: Jeans | B25: 42.53~58.8 元 | C25: 58.3
A26: Sweaters | B26: 35.43~43.41 元 | C26: 31.9
A27: Jumpsuits, Rompers & Overalls | B27: 39.65~58.32 元 | C27: 74.4
A28: Fashion Hoodies & Sweatshirts | B28: 31.74~48.92 元 | C28: 48.5
A29: Pants | B29: 33.5~39.79 元 | C29: 69
A30: Shorts | B30: 32.02~37.34 元 | C30: 86.1
A31: Leggings | B31: 35.0~45.0 元 | C31: 76.7
A32: Suiting & Blazers | B32: 32.65~40.14 元 | C32: 58.8
... A34: Bodysuits | B34: 28.19~35.99 元 | C34: 71.9

Sheet Sheet2
A1: 品类 | B1: 中高价位区间 | C1: 价格上涨占比（%）
A2: Tops, Tees & Blouses | B2: 25.0~30.0 元 | C2: 26.1
A3: Coats, Jackets & Vests | B3: 90.0~115.0 元 | C3: 38.1
A4: Dresses | B4: 49.5~59.42 元 | C4: 78.8
A5: Active | B5: 30.54~44.3 元 | C5: 35.5
A6: Jeans | B6: 42.53~58.8 元 | C6: 58.3
A7: Sweaters | B7: 35.43~43.41 元 | C7: 31.9
A8: Jumpsuits, Rompers & Overalls | B8: 39.65~58.32 元 | C8: 74.4
A9: Fashion Hoodies & Sweatshirts | B9: 31.74~48.92 元 | C9: 48.5
A10: Pants | B10: 33.5~39.79 元 | C10: 69
A11: Shorts | B11: 32.02~37.34 元 | C11: 86.1
A12: Leggings | B12: 35.0~45.0 元 | C12: 76.7
A13: Suiting & Blazers | B13: 32.65~40.14 元 | C13: 58.8
... A15: Bodysuits | B15: 28.19~35.99 元 | C15: 71.9

Sheet Sheet3
A1: B09YTWFM64 | B1: amazon.com/dp/B09YTWFM64
A2: B0D8PK4T1S | B2: amazon.com/dp/B0D8PK4T1S
A3: B0DMZC6ZB7 | B3: amazon.com/dp/B0DMZC6ZB7
A4: B0DMZ5MFWK | B4: amazon.com/dp/B0DMZ5MFWK
A5: B0C53BN4V8 | B5: amazon.com/dp/B0C53BN4V8
A10: B0BZH1CW8Q | B10: amazon.com/dp/B0BZH1CW8Q
A11: B09N61464Q | B11: amazon.com/dp/B09N61464Q
A12: B0BZH1KLJ5 | B12: amazon.com/dp/B0BZH1KLJ5
A13: B0DJWPMZZJ | B13: amazon.com/dp/B0DJWPMZZJ
A14: B0C5YP9YM7 | B14: amazon.com/dp/B0C5YP9YM7
A19: B07S7Z5LY7 | B19: amazon.com/dp/B07S7Z5LY7
A20: B0DHZVVGNW | B20: amazon.com/dp/B0DHZVVGNW
... A53: B0BCYXJTBP | B53: amazon.com/dp/B0BCYXJTBP
